Workbook

Sheet READ ME
A1: HAAS — Hyper-V Management Plane Comparison & Cost Model
A2: Built 17 Aug 2026 · Solution Engineer reference · All prices US list, USD, Azure meters priced East US
A4: PURPOSE
B5: Side-by-side comparison of every viable management plane for a Hyper-V based Hosted Private Cloud, with researched
B6: licensing cost for each. Written for a team and a customer base whose operational and architectural instincts come from
B7: VMware vSphere on Pure Storage — so every capability is mapped back to its VMware analogue.
A9: THE FIVE PLANES COMPARED
A10: 1. Classic | B10: Hyper-V Manager + Failover Cluster Manager + PowerShell/RSAT + sconfig. In-box, free, no management server to run.
A11: 2. SCVMM | B11: System Center 2025 Virtual Machine Manager. The vCenter-equivalent fabric manager. Licensed per managed HOST CORE.
A12: 3. WAC aMode | B12: Windows Admin Center 2606 (Jul 2026), Administration Mode. GA. Modern web GUI for single servers and clusters. Free.
A13: 4. WAC vMode | B13: Windows Admin Center VIRTUALIZATION MODE. Public Preview 2 (Apr 2026). Agent + PostgreSQL fleet manager.
B14: Scale target 1,000 hosts / 25,000 VMs — the same ceiling as SCVMM. Free.
A15: 5. Arc + SCVMM | B15: Azure Arc-enabled SCVMM. GA Nov 2023. Projects SCVMM inventory into Azure as ARM resources. The connector itself
B16: is free; the Azure services you layer on top are metered per VM per month.
A18: aMODE vs vMODE — THE DISTINCTION THAT MATTERS
B19: These are two SEPARATE, MUTUALLY EXCLUSIVE operational modes. Microsoft is explicit: 'You must install Windows Admin
B20: Center Administration Mode and Windows Admin Center Virtualization Mode on separate systems.'
B22: aMode = the classic stateless gateway. Talks WinRM/PowerShell per session. Guidance is 1-50 hosts. Extensible (Dell,
B23: HPE, Lenovo, Pure Storage all ship extensions). CredSSP double-hop is a recurring security tradeoff.
B24: vMode = stateful gateway backed by PostgreSQL, with an agent installed on every Hyper-V host. Built for parallel fleet
B25: operations at 1,000 hosts / 25,000 VMs. Introduces Resource Groups, Host Profiles, Network ATC intent templates,
B26: and VM templates. Auto-configures constrained Kerberos instead of leaning on CredSSP.
B28: Neither of these is 'WAC in the Azure portal' — that is a third thing entirely: a reverse-proxy access layer for Arc-enabled
B29: servers and Azure Local, with no gateway of your own, no third-party extensions, and a deliberately narrowed tool set.
A31: TABS
A32: Decision Guide | B32: START HERE. 10 qualifying questions, the short-version answers, full pros and cons per plane, and the framing mistakes to avoid.
A33: Feature Matrix | B33: 85 dimensions x 5 planes, with SEPARATE vSphere 8 and VCF 9 analogue columns. AutoFilter is on — filter column A to focus a conversation.
A34: Cost Model | B34: LIVE FORMULAS. Change the blue cells only. Models perpetual, SPLA, and Azure-metered scenarios over a chosen term.
A35: Hyper-V Advantages | B35: Where Hyper-V genuinely wins, rated STRONG / MODERATE / WEAK — plus a kill list of claims that will lose you the room.
A36: Objection Handling | B36: The 12 objections a VMware-native customer actually raises, with the factual answer and what to concede.
A37: SKU Reference | B37: Every price used, with channel, unit, confidence rating and source URL. Edit prices HERE — the Cost Model links to them.
A38: VMware Translation | B38: 40-row terminology map for retraining VMware-native staff and for customer-facing conversations.
A39: Sources & Caveats | B39: Where every number came from, and — more importantly — which ones are not safe to quote.
A41: vSPHERE 8 vs VCF 9 — WHY BOTH COLUMNS
B42: 55 of the 85 rows have a DIFFERENT answer under VCF 9 than under vSphere 8. Broadcom did not just rename things — it moved
B43: capability between products, bundled Aria into VCF Operations, replaced Cloud Director with VCF Automation, and removed a lot:
B44: Enhanced Linked Mode, vLCM baselines, Storage I/O Control, Storage DRS I/O balancing, N-VDS, Integrated Windows Auth, and
B45: classic vVols (deprecated). vCLS is deprecated and cannot be re-enabled in 9.1. Host Profiles are deprecated.
B46: Pink fill in the VCF 9 column marks every row where the answer changed. Know which version the customer is actually on —
B47: a vSphere 8 shop and a VCF 9 shop are having two different conversations.
...

Sheet Decision Guide
A1: Decision Guide — Which Management Plane?
A2: Work the questions in order. The first YES that eliminates a plane is decisive — do not re-litigate it further down.
A4: 1. THE QUALIFYING QUESTIONS — work top to bottom, stop when a plane is eliminated
A5: # Question | B5: If YES → | C5: If NO → | D5: Why this question decides it
A6: 1. Does the tenant require an air-gapped or sovereign environment with no outbound internet? | B6: ELIMINATE Arc-enabled SCVMM. Choose SCVMM, or Classic + WAC aMode. | C6: Arc stays on the table. Continue to Q2. | D6: Arc requires persistent outbound 443 and agents must check in. There is no disconnected mode. This is a hard architectural stop, not a preference.
A7: 2. Do you need to provision hosts from bare metal (BMC/PXE) as a repeatable workflow? | B7: SCVMM is the ONLY option. Nothing else does this. | C7: All planes remain viable. Continue to Q3. | D7: Bare-metal host provisioning via BMC/IPMI + WDS with physical computer profiles exists only in SCVMM. WAC (either mode) requires an OS already installed and domain-joined.
A8: 3. Do tenants get self-service, quotas, or a delegated portal? | B8: SCVMM (Clouds + self-service roles) or Arc-enabled SCVMM (Azure RBAC). Nothing else has it. | C8: Classic or WAC become viable. Continue to Q4. | D8: Classic RBAC is effectively 'are you a local administrator'. WAC's JEA roles are connection-scoped, not tenant-scoped with quotas. There is no middle option.
A9: 4. Do you need array-aware storage integration with Pure — classification, SAN-copy rapid provisioning? | B9: SCVMM (SMI-S/SMP provider). WAC aMode gives visibility only. | C9: WAC aMode's Pure extension may be enough. Continue to Q5. | D9: The Pure SMI-S/SMP provider only plugs into SCVMM. The Pure WAC extension gives monitoring, volume and initiator management, but no placement intelligence. vMode has NO Pure path at all today.
A10: 5. Do you need a DRS equivalent — automatic load balancing across the cluster? | B10: SCVMM Dynamic Optimization. Nothing else has it. | C10: Classic Node Fairness may suffice. Continue to Q6. | D10: Node Fairness is threshold-based rebalancing on join plus an optional 30-minute interval. Dynamic Optimization is scheduled (10-1440 min) with a 1-5 aggressiveness scale. Neither is continuous predictive DRS — set expectations.
A11: 6. Are you converting VMs FROM VMware as part of the engagement? | B11: SCVMM (V2V, ~4x faster in 2025) or a third party. Budget it separately. | C11: Continue to Q7. | D11: Classic has ZERO native V2V. This is a tooling decision independent of which plane runs the fabric day-to-day.
A12: 7. Is this fabric larger than roughly 50 hosts? | B12: SCVMM today. Track WAC vMode for when it reaches GA. | C12: Classic + WAC aMode is economically sensible. Continue to Q8. | D12: Microsoft's own guidance puts WAC Administration Mode at 1-50 hosts. vMode targets 1,000 hosts / 25,000 VMs — the same ceiling as SCVMM — but is Public Preview.
A13: 8. Is this a 2-4 node edge or small dedicated stack? | B13: Classic + WAC aMode. Do NOT license System Center for this. | C13: SCVMM is justified. Continue to Q9. | D13: System Center Datacenter adds ~59% to your Microsoft host licensing plus a SQL Server. On a 2-node edge cluster that overhead is indefensible.
A14: 9. Does the tenant already live in Azure, and will they accept an Azure dependency? | B14: Layer Arc-enabled SCVMM on top as an upsell. The connector is free. | C14: Stop at SCVMM. Do not introduce an Azure dependency the tenant did not ask for. | D14: Arc is additive, not alternative — it sits ON TOP of SCVMM. It adds Azure RBAC, Update Manager, Defender, Monitor and Cost Management, metered per VM per month.
A15: 10. Is the deployment going into production before mid-2027? | B15: Do NOT select WAC vMode. It is Public Preview with no HA design and self-signed certs only. | C15: vMode is a legitimate candidate — re-verify GA, HA, CA certs and Pure support first. | D15: vMode is the right strategic bet and the wrong thing to sign a SOW against in 2026. Revisit at the 2027 planning cycle.
A17: 2. THE SHORT VERSION — what the questions usually add up to
A18: Situation | B18: Answer | C18: Because
A19: Core HAAS multi-tenant fabric | B19: SCVMM 2025 as the fabric of record, with WAC aMode alongside as the day-2 GUI and Pure visibility layer. | C19: SCVMM is the only plane that does bare-metal provisioning, tenant clouds with quotas, Pure array integration and V2V. Those four are table stakes for the business.
A20: Tenant already in Azure, accepts the dependency | B20: Add Arc-enabled SCVMM on top as a paid upsell. | C20: The connector is free. You are selling Azure RBAC self-service, Update Manager, Defender and Cost Management — priced per VM per month.
A21: Air-gapped or sovereign tenant | B21: SCVMM + WAC aMode. Arc is off the table entirely. | C21: Arc requires persistent outbound 443 with no disconnected mode. This is architectural, not negotiable.
A22: 2-4 node edge or small dedicated stack | B22: Classic + WAC aMode. Do not licence System Center. | C22: System Center adds ~59% to Microsoft host licensing plus a SQL Server. Indefensible at that size.
A23: Anything going live before mid-2027 | B23: Do not select WAC vMode. | C23: Public Preview, no HA design, self-signed certs only, no Pure path. Right bet, wrong year.
A24: Lab / evaluation track for 2027 | B24: Stand up WAC vMode now and re-assess at the 2027 planning cycle. | C24: Gate the re-assessment on four things: GA, a documented HA design, CA certificate support, and a Pure Storage integration path.
A26: 3. PROS AND CONS BY PLANE
A27: Plane | B27: Pros | C27: Cons | D27: Pick it when | E27: Walk away when
A28: 1. Classic (Hyper-V Mgr + FCM + PowerShell) | B28: + Zero incremental licence cost — it is in the box + No management server to build, patch, licence or make highly available + Deepest PowerShell surface of any plane + Fully air-gap capable, zero Azure dependency + Nothing extra to upgrade — lifecycle is just Windows Server's + Cluster-Aware Updating is genuinely good and free + Shielded VMs / HGS fully supported natively | C28: – No central inventory at all — the single biggest shock for vCenter-trained staff – RBAC is effectively local Administrators membership – No bare-metal provisioning, no templates, no library, no self-service – ZERO native VMware V2V – Cluster Sets deprecated in WS2025 — the multi-cluster story is dead – No Pure Storage integration beyond the REST SDK – GPU-P and nested virt are PowerShell-only, no GUI – Capacity planning and alerting are DIY scripting | D28: 2-4 node edge sites, dedicated single-tenant stacks, lab and burn-in, or as the always-present fallback when a management plane is down. | E28: Any multi-tenant fabric, anything over ~2 clusters, or any engagement where the customer expects a vCenter-like experience.
A29: 2. SCVMM 2025 | B29: + The only plane with bare-metal host provisioning + The only plane with a true DRS equivalent (Dynamic Optimization) and Power Optimization + Clouds give a real on-prem tenant abstraction with quotas and self-service roles + Pure Storage SMI-S/SMP: array-aware placement and SAN-copy rapid provisioning + Native V2V from VMware, ~4x faster in the 2025 release + Templates, hardware/guest profiles, service templates, library server + Logical networks, MAC/IP pools, VIP templates, load balancer integration + 1,000 hosts / 25,000 VMs, supported to Jan 2035 + The easiest conceptual bridge for VMware-native staff — maps to vCenter almost 1:1 + Fully air-gap capable | C29: – ~59% uplift on your Microsoft host licensing, per managed host core – Requires SQL Server — Express is not supported for the VMM database – You must make VMM itself highly available, plus the SQL behind it – Its own upgrade cadence and Update Rollup discipline to maintain – Dated console UX compared to WAC – Microsoft is narrowing its Azure surface: SPF discontinued, Azure VM mgmt removed – Only supports upgrade from VMM 2022 — no direct jump from 2016/2019 | D29: Any multi-tenant HAAS fabric. Anywhere you need bare-metal provisioning, tenant clouds, Pure array integration, or V2V. This is the default answer for the core business. | E29: 2-4 node edge deployments where the licensing and SQL overhead cannot be justified.
A30: 3. WAC Administration Mode (2606, GA) | B30: + Genuinely $0 — Microsoft states it explicitly + Modern web GUI; low learning curve for VMware-native staff + Best S2D day-2 experience available, including the HCI dashboard + Extensible: Dell OMIMSWAC, HPE, Lenovo XClarity, and the Pure Storage extension + VM Conversion extension gives a V2V path (preview) + Storage Migration Service included + Air-gap capable, no Azure dependency + HA is documented and supported via Deploy-GatewayV2Ha | C30: – Microsoft's own guidance caps it at roughly 1-50 hosts – No tenant self-service, no quotas, no cloud abstraction – No bare-metal provisioning, no VM templates – CredSSP double-hop is a recurring security tradeoff – Modern Lifecycle: you must upgrade within 30 days of each release to stay supported – RBAC is coarse — connection-scoped, not tenant-scoped – Pure extension gives visibility only, no placement intelligence | D30: As the day-2 GUI and hardware/Pure visibility layer ALONGSIDE SCVMM, and as the primary plane for small dedicated or edge stacks. | E30: As the sole plane for a large multi-tenant fabric. It was not designed for that and Microsoft says so.
A31: 4. WAC Virtualization Mode (vMode — Public Preview 2) | B31: + Genuinely $0 + Built for fleet scale: 1,000 hosts / 25,000 VMs, matching SCVMM's ceiling + Stateful — PostgreSQL backend plus per-host agents enable true parallel operations + Auto-configures constrained Kerberos instead of relying on CredSSP + VM templates — the capability aMode never had + First plane with a first-class GPU-P UI + Resource Groups, Host Profiles, Network ATC intent templates + Air-gap capable, no Azure dependency + Clear evidence Microsoft is investing in the on-prem fabric story | C31: – PUBLIC PREVIEW — not supported for production – NO documented HA design at all, unlike aMode – Self-signed 60-day certificates ONLY; CA certs not yet available – Storage and Networking host profiles still unavailable in preview – S2D / hyperconverged storage explicitly not available yet – NO Pure Storage integration path today – Managed hosts must be Datacenter edition, and onboarding forces a rolling VM-draining reboot – Cannot coexist with aMode — Microsoft requires separate systems – No bare-metal provisioning, no tenant self-service | D31: Lab evaluation now. Re-assess at the 2027 planning cycle, gated on four things: GA, a documented HA design, CA certificate support, and a Pure Storage path. | E31: Anything going to production before mid-2027, and anything with a signed SLA behind it.
A32: 5. Arc-enabled SCVMM | B32: + The connector, control plane and resource bridge are all FREE + Real self-service through Azure RBAC — the best tenant portal of any plane + VMs become ARM resources: first-party Terraform, Bicep and full REST + Azure Update Manager for guest patching — the best of any plane + Defender for Cloud gives real security posture management + Azure Monitor, Cost Management, Activity Log audit trail + Azure Lighthouse (free) enables cross-tenant delegated management + Update Manager and Guest Config are FREE if hosts carry WS SA, PAYG, or Defender P2 | C32: – NOT air-gap capable — requires persistent outbound 443. Hard stop for sovereign tenants – Additive only — you still need SCVMM underneath and must licence it – Azure services are metered per VM per month and accumulate quickly – Resource bridge consumes 4 vCPU / 32 GB / 100 GB of your capacity – Static IPs only, 3 contiguous, plus an extensive firewall allow-list – Max 15,000 VMs per SCVMM server connection – Tenant must accept an Azure dependency and an Entra ID relationship – Microsoft's own 'choose an Arc service' guide omits Arc-SCVMM entirely — Azure Local is the favoured path | D32: As a per-tenant UPSELL on top of SCVMM, where the tenant already lives in Azure and wants one control plane across on-prem and cloud. | E32: Air-gapped or sovereign tenants, cost-sensitive tenants, or anywhere the customer has no existing Azure footprint.
A34: 4. THINGS THAT ARE NOT A CHOICE — common mistakes when framing this decision
A35: Arc is not an alternative to SCVMM — it sits ON TOP of it. | B35: You still buy and run SCVMM underneath. Arc adds an Azure control plane; it does not replace the fabric manager.
A36: WAC aMode and vMode cannot coexist on the same system. | B36: Microsoft requires them on separate systems. Choosing vMode means standing up a second, parallel management estate.
A37: WAC is not an alternative to SCVMM for a multi-tenant fabric. | B37: Microsoft's own FAQ: they are complementary. WAC replaces the MMC snap-ins, not System Center's fabric and monitoring role.
A38: The migration tool is a separate decision from the management plane. | B38: You may run Classic day-to-day and still need SCVMM or a third party purely to convert VMs off VMware. Budget it separately.
A39: Classic is not a 'cheaper SCVMM'. | B39: It is a different operating model with no central inventory. Staff cost, not licence cost, is where the difference shows up.
A40: Azure Local is not in this comparison, and that is deliberate. | B40: It is a different product with its own hardware catalogue, billing model and Arc dependency. If it belongs on the table, it needs its own evaluation.

Sheet Feature Matrix
A1: Feature Matrix — Hyper-V Management Planes
A2: Full / Partial / Scripted only / None. AutoFilter is on row 4 — filter column A to focus one category. VMware analogue in column H.
H3: → pink fill in the VCF 9 column = Broadcom changed this vs vSphere 8
A4: Category | B4: Dimension | C4: 1. Classic (HV Mgr + FCM + PS) | D4: 2. SCVMM 2025 | E4: 3. WAC aMode (2606, GA) | F4: 4. WAC vMode (Preview 2) | G4: 5. Arc + SCVMM | H4: VMware analogue vSPHERE 8 | I4: VMware analogue VCF 9 (current) | J4: Note / why it matters for HAAS
A5: Core VM Ops | B5: VM lifecycle (create/delete/start/stop) | C5: Full | D5: Full | E5: Full | F5: Full | G5: Full | H5: vSphere Client / PowerCLI | I5: vSphere Client / PowerCLI | J5: All planes cover basic lifecycle. Classic = per-host console only.
A6: Core VM Ops | B6: Checkpoints (Standard + Production) | C6: Full | D6: Full | E6: Full | F6: Not documented in preview | G6: Partial | H6: Snapshot | I6: Snapshot (VSS-quiesced via Tools) | J6: Production checkpoints are VSS/app-consistent - closer to a 'snapshot done right'.
A7: Core VM Ops | B7: Export / Import VM | C7: Full | D7: Full | E7: Full | F7: Partial | G7: None | H7: OVF/OVA export | I7: OVF/OVA export | J7: Classic Export-VM/Import-VM is the baseline everything else wraps.
A8: Core VM Ops | B8: Live Migration (in-cluster) | C8: Full | D8: Full | E8: Full | F8: Full | G8: Full | H8: vMotion | I8: vMotion | J8: Full parity with vMotion.
A9: Core VM Ops | B9: Shared-nothing Live Migration | C9: Full | D9: Full | E9: Full | F9: Full | G9: Partial | H9: Enhanced vMotion (XVC) | I9: Enhanced vMotion (XVC) | J9: Kerberos constrained delegation or cert auth required.
A10: Core VM Ops | B10: Storage Live Migration | C10: Full | D10: Full | E10: Full | F10: Partial | G10: Partial | H10: Storage vMotion | I10: Storage vMotion | J10: Move-VMStorage / Move-VM -IncludeStorage.
A11: Core VM Ops | B11: Console access (VMConnect / Enhanced Session) | C11: Full | D11: Full | E11: Full | F11: Full | G11: Partial | H11: VM Web/Remote Console | I11: VM Web Console | J11: Classic uses vmconnect.exe. Arc gives portal-based serial/RDP paths, not a true VM console.
A12: Core VM Ops | B12: Tenant-facing web console | C12: None | D12: Partial | E12: Partial | F12: Partial | G12: Full | H12: VM Web Console | I12: VCF Automation console | J12: Arc/Azure portal is the only plane with a real delegated web console for end tenants.
A13: Core VM Ops | B13: Nested virtualization | C13: Scripted only | D13: Partial | E13: Scripted only | F13: Scripted only | G13: Scripted only | H13: Nested ESXi | I13: Nested ESXi | J13: PowerShell only. No GUI in ANY plane - surprises VMware admins.
A14: Core VM Ops | B14: GPU - DDA passthrough | C14: Scripted only | D14: Partial | E14: Partial | F14: Full | G14: Partial | H14: vGPU / DirectPath I/O | I14: Assignable Hardware / Private AI Foundation | J14: vMode ships a dedicated GPU-P tool; Classic is 100% PowerShell.
A15: Core VM Ops | B15: GPU-P (partitioning) | C15: Scripted only | D15: Partial | E15: Partial | F15: Full | G15: Partial | H15: NVIDIA vGPU profiles | I15: vGPU + Private AI Foundation; vMotion ~6x faster | J15: vMode is the first plane with a first-class GPU-P UI.
... A89: Skills & GTM | B89: Incremental licensing cost vs Classic | C89: Baseline ($0) | D89: +System Center per host + SQL | E89: $0 | F89: $0 | G89: +Azure consumption per VM/host | H89: - | I89: Per-core subscription, 16-core/CPU minimum | J89: See the Cost Model tab for modelled figures.

Sheet Cost Model
A1: Cost Model — 3 Scenarios × 5 Management Planes
A2: Edit ONLY the blue cells. Everything else recalculates. Prices link from the SKU Reference tab.
A4: 1. FABRIC INPUTS — edit the blue cells only
A5: Hyper-V hosts in the fabric (physical nodes, including N+1 spare) | B5: 8
A6: Physical CPU sockets per host | B6: 2
A7: Physical cores per socket | B7: 32
A8: Total physical cores per host | B8: =B6*B7 -> 64 | C8: Sanity-check against the actual CPU SKU on the BOM.
A9: Licensable cores per host | B9: =MAX(B8,B6*8,16) -> 64 | C9: Microsoft minimum: 8 cores/socket AND 16 cores/server, whichever is greater. Applies to BOTH Windows Server and System Center.
A10: 2-core license packs per host | B10: =B9/2 -> 32
A11: Total licensable cores across the fabric | B11: =B5*B9 -> 512
A12: Average VMs per host | B12: 40
A13: Total VMs in the fabric | B13: =B5*B12 -> 320
A14: Term modelled (years) | B14: 3
A15: Software Assurance rate (% of license per year) | B15: 0.25 | C15: Analyst benchmark, NOT Microsoft-published. Applied to years 2..N. Note: unlimited virtualisation on Datacenter is a base right, not an SA benefit.
A16: N+1 — hosts held as spare capacity | B16: 1 | C16: 0 for N+0, 2 for N+2. You still LICENSE the spare; it just does not carry chargeable workload.
A17: Effective workload hosts after N+1 | B17: =MAX(B5-B16,0) -> 7
A18: Effective VMs after N+1 (chargeable capacity) | B18: =B17*B12 -> 280 | C18: Use THIS as the denominator when quoting a per-VM price to a tenant.
A19: SQL Server cores licensed for the VMM database | B19: 4 | C19: 4-core minimum. SQL Express is NOT a supported VMM 2025 database. Verify with your LSP whether System Center's bundled SQL runtime rights cover this.
A20: Waive Update Manager + Guest Config? Y / N | B20: Y | C20: Y if hosts carry Windows Server SA, WS pay-as-you-go, or Defender for Servers P2 — Microsoft makes both free in that case.
A21: Log Analytics GB ingested per VM per month | B21: 2 | C21: PLANNING ESTIMATE ONLY — Microsoft publishes no per-server figure. Typical VM Insights range is 1-3 GB.
A23: 2. PRICE BOOK — green cells link to the SKU Reference tab; change prices THERE, not here
A24: Windows Server 2025 Datacenter — per 2-core pack (perpetual) | B24: ='SKU Reference'!$F$6 -> 846.38
A25: Windows Server Datacenter — per 2-core pack / month (SPLA) | B25: ='SKU Reference'!$F$9 -> 25 | C25: LOW CONFIDENCE — reseller midpoint.
A26: Windows Server 2025 pay-as-you-go via Arc — per core / month | B26: ='SKU Reference'!$F$11 -> 33.58
A27: System Center 2025 Datacenter — per 2-core pack (perpetual) | B27: ='SKU Reference'!$F$16 -> 496
A28: System Center Datacenter — per 2-core pack / month (SPLA) | B28: ='SKU Reference'!$F$21 -> 21 | C28: LOW CONFIDENCE — reseller midpoint.
A29: SQL Server Standard — per core (perpetual) | B29: ='SKU Reference'!$F$23 -> 1859
A30: Windows Admin Center (aMode and vMode) | B30: ='SKU Reference'!$F$25 -> 0 | C30: Confirmed $0 by Microsoft.
A31: Azure Update Manager — per server / month | B31: ='SKU Reference'!$F$28 -> 5
A32: Defender for Servers Plan 2 — per server / month | B32: ='SKU Reference'!$F$30 -> 14.6
A33: Azure Policy Guest Config + Change Tracking — per server / month | B33: ='SKU Reference'!$F$31 -> 6
A34: Azure Monitor Log Analytics — per GB | B34: ='SKU Reference'!$F$32 -> 2.3
A35: Azure Arc control plane + Arc-enabled SCVMM connector | B35: ='SKU Reference'!$F$26 -> 0 | C35: Free. Includes the resource bridge.
A36: Azure Local host service fee — per core / month | B36: ='SKU Reference'!$F$38 -> 10 | C36: Reference only — not used in the totals below.
A38: 3. SCENARIO A — PERPETUAL LICENSING (Open / CSP) + Software Assurance
A39: Cost line | B39: 1. Classic | C39: 2. SCVMM | D39: 3. WAC aMode | E39: 4. WAC vMode | F39: 5. Arc + SCVMM
A40: Windows Server 2025 Datacenter — license, all hosts | B40: =$B$5*$B$10*$B$24 -> 216673.28 | C40: =$B$5*$B$10*$B$24 -> 216673.28 | D40: =$B$5*$B$10*$B$24 -> 216673.28 | E40: =$B$5*$B$10*$B$24 -> 216673.28 | F40: =$B$5*$B$10*$B$24 -> 216673.28
A41: System Center 2025 Datacenter — license, all managed hosts | B41: 0 | C41: =$B$5*$B$10*$B$27 -> 126976 | D41: 0 | E41: 0 | F41: =$B$5*$B$10*$B$27 -> 126976
A42: SQL Server Standard — VMM database | B42: 0 | C42: =$B$19*$B$29 -> 7436 | D42: 0 | E42: 0 | F42: =$B$19*$B$29 -> 7436
A43: Windows Admin Center | B43: 0 | C43: 0 | D43: =$B$30 -> 0 | E43: =$B$30 -> 0 | F43: 0
...

Sheet SKU Reference
A1: SKU & Price Reference
A2: EDIT PRICES HERE — the Cost Model links to column F. Check the Confidence column before any number reaches a customer.
A4: Ref | B4: Product | C4: Edition | D4: Channel | E4: Unit | F4: Price (USD) | G4: Confidence | H4: Price date | I4: Source URL | J4: Note / licensing rule
A5: WS-DC-16 | B5: Windows Server 2025 Datacenter | C5: Datacenter | D5: Perpetual / Open ERP | E5: per 16-core server license | F5: 6771 | G5: HIGH - Microsoft pricing page | H5: Aug 2026 | I5: https://www.microsoft.com/en-us/windows-server/pricing | J5: 16-core minimum per server; 8-core minimum per socket. Unlimited Windows guest OSEs once all physical cores licensed.
A6: WS-DC-2 | B6: Windows Server 2025 Datacenter | C6: Datacenter | D6: Perpetual / Open ERP | E6: per 2-core pack | F6: 846.38 | G6: MED - derived (6771/8) | H6: Aug 2026 | I6: https://www.microsoft.com/en-us/windows-server/pricing | J6: Derived from the 16-core figure. Use for hosts above 16 cores.
A7: WS-STD-16 | B7: Windows Server 2025 Standard | C7: Standard | D7: Perpetual / Open ERP | E7: per 16-core server license | F7: 1176 | G7: HIGH - Microsoft pricing page | H7: Aug 2026 | I7: https://www.microsoft.com/en-us/windows-server/pricing | J7: Grants only 2 virtual OSEs. Must re-license ALL cores again for every additional 2 VMs.
A8: WS-STD-2 | B8: Windows Server 2025 Standard | C8: Standard | D8: Perpetual / Open ERP | E8: per 2-core pack | F8: 147 | G8: MED - derived (1176/8) | H8: Aug 2026 | I8: https://www.microsoft.com/en-us/windows-server/pricing | J8: Derived.
A9: WS-DC-SPLA | B9: Windows Server Datacenter | C9: Datacenter | D9: SPLA (hosting) | E9: per 2-core pack / month | F9: 25 | G9: LOW - reseller midpoint of $22-28 range | H9: 2026 | I9: https://redresscompliance.com/microsoft-spla-pricing-2026.html | J9: SPLA list is contractually confidential. GET A QUOTE from your SPLA distributor before committing.
A10: WS-STD-SPLA | B10: Windows Server Standard | C10: Standard | D10: SPLA (hosting) | E10: per 2-core pack / month | F10: 5 | G10: LOW - reseller midpoint of $4-6 range | H10: 2026 | I10: https://redresscompliance.com/microsoft-spla-pricing-2026.html | J10: Same caveat. SPLA pricing held flat for the Jan 2026 refresh (FX adjustments only).
A11: WS-PAYG | B11: Windows Server 2025 pay-as-you-go via Azure Arc | C11: Std or DC (same rate) | D11: Azure Arc subscription | E11: per physical core / month | F11: 33.58 | G11: MED-HIGH - $0.046/core/hr | H11: Aug 2026 | I11: https://learn.microsoft.com/azure/azure-arc/servers/billing-windows-server-pay-go | J11: Microsoft docs confirm Standard and Datacenter bill at the SAME rate. No CPU core minimum. AVMA NOT available. RDS CALs still required.
A12: WS-CAL-DEV | B12: Windows Server 2025 Device CAL | C12: - | D12: Reseller retail | E12: per device | F12: 29.99 | G12: LOW - reseller listing, no MS list price | H12: Aug 2026 | I12: https://www.cdw.com/product/microsoft-windows-server-2025-standard-license-1-device-cal/8143166 | J12: NOT needed in a SPLA hosting model - use SALs instead.
A13: WS-CAL-RDS | B13: Windows Server 2025 RDS User CAL | C13: - | D13: Reseller retail | E13: per user | F13: 129.99 | G13: LOW-MED - single reseller listing | H13: Aug 2026 | I13: https://www.cdw.com/product/microsoft-windows-server-2025-remote-desktop-services-license-1-user-ca/8143188 | J13: RDS CALs are required even under Arc pay-as-you-go.
A14: RDS-SAL | B14: RDS Subscriber Access License | C14: - | D14: SPLA (hosting) | E14: per subscriber / month | F14: 6.5 | G14: LOW - reseller midpoint of $5-8 | H14: 2026 | I14: https://redresscompliance.com/microsoft-spla-pricing-2026.html | J14: The hosting-model equivalent of an RDS CAL.
A15: SC-DC-16 | B15: System Center 2025 Datacenter | C15: Datacenter | D15: Perpetual + SA / Open | E15: per 16-core server license | F15: 3968 | G15: HIGH - Microsoft pricing datasheet | H15: Nov 2024 datasheet | I15: https://www.microsoft.com/content/dam/microsoft/final/en-us/microsoft-brand/documents/System-Center-2025-Pricing-Datasheet.pdf | J15: +10% vs System Center 2022. ALL physical cores of every managed host must be licensed.
A16: SC-DC-2 | B16: System Center 2025 Datacenter | C16: Datacenter | D16: Perpetual + SA / Open | E16: per 2-core pack | F16: 496 | G16: MED - derived (3968/8) | H16: Nov 2024 | I16: https://www.microsoft.com/content/dam/microsoft/final/en-us/microsoft-brand/documents/System-Center-2025-Pricing-Datasheet.pdf | J16: Derived.
... A40: SA-RATE | B40: Software Assurance (server products) | C40: - | D40: Volume Licensing | E40: % of license price / year | F40: 0.25 | G40: MED - two independent analyst sources agree | H40: 2026 | I40: https://upperedge.com/microsoft/microsoft-software-assurance-big-risk-for-a-small-reward/ | J40: NOT a Microsoft-published percentage. Note: unlimited virtualization on Datacenter is a BASE license right, NOT an SA benefit.

Sheet VMware Translation
A1: VMware → Hyper-V Translation Table
A2: For retraining vSphere-native staff and for customer conversations. Fidelity column is deliberately blunt about where there is no equivalent.
A4: VMware concept | B4: Hyper-V / Windows Server equivalent | C4: Fidelity | D4: Note
A5: vCenter Server | B5: SCVMM (fabric) or WAC vMode (cluster fleet) | C5: Partial | D5: No single 1:1. Classic has NO central inventory at all - biggest conceptual gap for VMware staff.
A6: vSphere Client | B6: WAC (Administration Mode) / VMM Console | C6: Good | D6: WAC aMode is the closest modern web UI.
A7: ESXi Host Client | B7: Hyper-V Manager | C7: Good | D7: Both are single-target, no aggregation.
A8: PowerCLI | B8: Hyper-V + FailoverClusters PowerShell modules | C8: Good | D8: Comparable cmdlet depth, but no cross-host object model - you write the loops.
A9: vMotion | B9: Live Migration (Move-VM) | C9: Exact | D9: Full parity.
A10: Storage vMotion | B10: Storage Migration (Move-VMStorage) | C10: Exact | D10: Full parity.
A11: Enhanced vMotion (no shared storage) | B11: Shared-nothing Live Migration | C11: Exact | D11: Full parity.
A12: vSphere HA | B12: Failover Clustering | C12: Exact | D12: Restart-on-failure semantics are equivalent.
A13: Fault Tolerance (lockstep) | B13: NO EQUIVALENT | C13: None | D13: Be explicit with customers. Nothing in Hyper-V does lockstep FT.
A14: DRS | B14: SCVMM Dynamic Optimization | C14: Partial | D14: Classic only has basic Node Fairness. No predictive/what-if simulation in any plane.
A15: DPM (Distributed Power Mgmt) | B15: SCVMM Power Optimization | C15: Partial | D15: SCVMM only, requires BMC.
... A44: Cross-vCenter linked mode | B44: Cluster Sets (DEPRECATED WS2025) | C44: None | D44: Do not build on Cluster Sets. Use SCVMM or vMode for multi-cluster.

Sheet Sources & Caveats
A1: Sources, Assumptions & Caveats
A2: Everything below was verified against a live source in August 2026. Read the CAVEATS block before quoting anything.
A4: Topic | B4: What we established | C4: Source
A5: Windows Server pricing | B5: WS 2025 Datacenter $6,771 per 16-core server licence; Standard $1,176. Datacenter grants unlimited Windows guest OSEs once all physical cores are licensed. Minimums: 8 cores/socket, 16 cores/server. | C5: https://www.microsoft.com/en-us/windows-server/pricing
A6: Windows Server Standard restack | B6: Standard grants 2 virtual OSEs. Every additional 2 VMs requires re-licensing ALL physical cores again — not incremental cores. A host needing 8 VMs requires 4x the full core stack. | C6: https://learn.microsoft.com/answers/a/12670642
A7: Windows Server pay-as-you-go | B7: Standard and Datacenter bill at the SAME rate via Arc. No minimum core count. AVMA is NOT available under PAYG — each VM needs its own licence. RDS CALs are still required. $0.046/core/hr ≈ $33.58/core/month. | C7: https://learn.microsoft.com/azure/azure-arc/servers/billing-windows-server-pay-go
A8: System Center pricing | B8: System Center 2025 Datacenter $3,968 per 16-core server; Standard $1,455. Both up ~10% vs System Center 2022. | C8: https://www.microsoft.com/content/dam/microsoft/final/en-us/microsoft-brand/documents/System-Center-2025-Pricing-Datasheet.pdf
A9: System Center core rule | B9: ALL physical cores on every managed host must be licensed — 8/socket, 16/server minimum. Partial-core licensing is not permitted, even with cores parked via Intel SST-PP. | C9: https://www.microsoft.com/en-us/licensing/product-licensing/system-center
A10: SCVMM not sold standalone | B10: 'Components included in the server MLs are not available separately.' You cannot buy SCVMM alone — it is the full System Center suite or nothing, in every channel including SPLA. | C10: https://www.microsoft.com/en-us/licensing/product-licensing/system-center
A11: System Center lifecycle | B11: System Center 2025 VMM: mainstream support ends 9 Jan 2030; extended support ends 10 Jan 2035. All System Center 2025 components share these dates. | C11: https://learn.microsoft.com/lifecycle/products/system-center-2025-virtual-machine-manager
A12: SCVMM 2025 scale | B12: Tested maxima: 1,000 hosts, 25,000 VMs, 1,000 services, 1,000 user roles, 20 clouds, 2,000 virtual networks. Upgrade path is VMM 2022 → 2025 only. | C12: https://learn.microsoft.com/system-center/vmm/system-requirements?view=sc-vmm-2025
A13: SCVMM 2025 changes | B13: SPF (Service Provider Foundation) is DISCONTINUED. Azure VM management from VMM and Azure Update Management v1 are no longer supported — Microsoft directs you to Arc-enabled SCVMM. ESXi→Hyper-V conversion is ~4x faster. | C13: https://learn.microsoft.com/system-center/vmm/whats-new-in-vmm?view=sc-vmm-2025
A14: SQL for the VMM database | B14: SQL Server 2019/2022/2025 Standard, Enterprise or Datacenter. SQL Express is NOT listed as supported. Budget licensed SQL Standard at minimum. Some sources claim System Center bundles SQL runtime rights for its own databases — this could NOT be confirmed on a Microsoft page for 2025. Verify with your LSP. | C14: https://learn.microsoft.com/system-center/vmm/system-requirements?view=sc-vmm-2025#sql-server
A15: WAC is free | B15: 'Windows Admin Center has no additional cost beyond Windows. You can use Windows Admin Center with valid licenses of Windows Server or Windows client at no additional cost.' Applies to every install topology including vMode. | C15: https://learn.microsoft.com/windows-server/manage/windows-admin-center/understand/faq
... A40: Microsoft's own positioning | B40: Microsoft states WAC and SCVMM are complementary: 'Windows Admin Center is intended to replace the traditional MMC snap-ins and the server admin experience. Windows Admin Center isn't intended to replace the monitoring aspects of SCVMM.' | C40: https://learn.microsoft.com/windows-server/manage/windows-admin-center/understand/faq
A42: CAVEATS — READ BEFORE ANY NUMBER LEAVES THIS FILE
A43: SPLA figures are estimates | B43: Microsoft does not publish SPLA list prices; they are contractually confidential and visible only to signed SPLA partners. Every SPLA rate in this workbook is a reseller-published midpoint of a range (WS Datacenter $22-28, WS Standard $4-6, System Center Datacenter $18-24, System Center Standard $5-8, RDS SAL $5-8, all per 2-core pack or per subscriber per month). Get a written quote from your SPLA distributor before Scenario B reaches a customer.
A44: CAL prices are reseller retail | B44: Microsoft's own CAL page explicitly directs buyers to a reseller rather than showing a price. The CAL figures here are live reseller listings, not Microsoft list. In a SPLA hosting model you use SALs, not perpetual CALs, so this mostly does not apply to HAAS.
A45: Software Assurance rate is an analyst benchmark | B45: The 25%/year figure for server products is widely cited by two independent analyst sources but is not a Microsoft-published percentage. Also note: unlimited virtualisation on Datacenter is a BASE licence right, not an SA benefit — you do not need SA to run unlimited Windows guests on a fully licensed Datacenter host.
A46: Two Azure rates are secondary-sourced | B46: Azure Update Manager (~$5/server/month) and Guest Configuration + Change Tracking (~$6/server/month): the billing MODEL is confirmed in Microsoft docs, but the exact rates come from third-party sources — the meters are not exposed in the public Retail Prices API. Validate in the Azure Pricing Calculator against your actual EA/CSP agreement. Note both are free under the SA / PAYG / Defender P2 waiver.
A47: Log Analytics volume is a planning estimate | B47: Microsoft publishes no per-server GB figure for VM Insights. The 1-3 GB/server/month range used here is an industry rule of thumb. Verbose security-event or Sentinel collection will be materially higher. Measure it in a pilot before committing to a per-VM price.
A48: Windows Server PAYG rate — one conflict resolved | B48: One analyst blog claims Datacenter PAYG is ~$67/core/month against ~$34 for Standard. This contradicts Microsoft's explicit statement that both editions bill at the same rate. We used $33.58 for both. If a large PAYG deal is on the table, confirm the meter directly.
A49: System Center bundled SQL rights — unresolved | B49: Several third-party licensing guides assert that System Center Server MLs include limited SQL Server runtime rights for System Center's own databases, which would remove the SQL line from the Cost Model. This could not be confirmed on any Microsoft Learn or microsoft.com page for System Center 2025. The model includes the SQL cost conservatively. Confirm with your LSP — it is worth roughly $7.4k on a 4-core deployment.
A50: vMode is a moving target | B50: Everything documented here about Virtualization Mode reflects Public Preview 2 as of Aug 2026. The HA gap, the certificate limitation, and the missing storage/networking host profiles are all preview-stage issues that Microsoft may close. Re-verify before the 2027 planning cycle.
A51: Feature verdicts are documentation-based | B51: The Full/Partial/None verdicts come from Microsoft's published documentation, not from lab validation in the HAAS environment. Where a capability is business-critical to a specific deal, prove it in the lab before it goes in a statement of work.

Sheet Hyper-V Advantages
A1: Where Hyper-V Genuinely Wins
A2: Rated STRONG / MODERATE / WEAK. Lead with STRONG only. The kill list at the bottom is the important part — those claims lose you the room.
A4: Area | B4: The claim | C4: Strength | D4: The evidence | E4: How to use it — and what NOT to say
A5: Licensing | B5: Windows Server Datacenter includes UNLIMITED Windows guest OSE licensing once all physical cores are licensed. | C5: STRONG | D5: Microsoft 'locks and limits' page: Standard = 2 VMs per licensed host; Datacenter = unlimited VMs. On vSphere/VCF the customer pays Broadcom for the platform AND Microsoft for every Windows guest — Windows Server licensing does not get cheaper because you run ESXi. | E5: THE headline economic argument. On a Windows-heavy estate the guest OS licensing you must buy anyway collapses into the host licence. Works without attacking VMware's product quality at all — it is pure licensing math.
A6: Licensing | B6: Microsoft's core minimum is HALF of Broadcom's. | C6: STRONG | D6: Windows Server: 8 cores/socket, 16 cores/server minimum. VCF/VVF: 16 cores per CPU minimum, even if the CPU has fewer. On a 2-socket 8-core/socket host, Windows bills 16 cores (exactly what you have); VCF bills 32. | E6: Mechanically verifiable from both vendors' own docs. Worst on low-core-density hosts. One compliance firm measures 10-30% 'phantom cores' across the renewals they reviewed.
A7: Licensing | B7: Perpetual licensing is still available from Microsoft. Broadcom is subscription-only. | C7: STRONG | D7: Windows Server 2025 and System Center 2025 both still sell perpetually, with an optional Arc pay-as-you-go subscription as a CHOICE. Broadcom ended perpetual VMware licensing and support renewal entirely. | E7: Frame as optionality and capex/opex control, not as 'subscriptions are bad'. Some customers prefer subscription.
A8: Licensing | B8: SPLA remains open and stable for hosters. The VCSP program has contracted sharply. | C8: STRONG | D8: SPLA is a standard, broadly available monthly-reporting model. Broadcom terminated the VCSP White Label / rental resale model (31 Oct 2025) and closed the VCSP Advantage program to an invite-only model (26 Jan 2026) — press reports as few as ~19 VCSP providers left in the entire US. | E8: THE most relevant argument for HAAS specifically. This is not a price argument, it is a business-continuity argument: your ability to keep selling VMware capacity at all is now gated by Broadcom's partner-tier decisions.
A9: Licensing | B9: Documented customer disputes over Broadcom renewal pricing. | C9: MODERATE | D9: AT&T's 2024 lawsuit ALLEGES a proposed 1,050% increase across ~75,000 VMs / ~8,600 servers. Tesco publicly cited 'abusive conduct'. Four European industry associations wrote jointly to EU leadership citing steep increases. | E9: Say 'AT&T alleges', never 'Broadcom raised prices 1,050%'. Broadcom's counter-position is that full-VCF-bundle customers pay less overall. Present as 'public disputes exist', not as settled fact — overstating this loses the room.
A10: Security | B10: Shielded VMs + Host Guardian Service give an attestation-based guarded fabric. | C10: MODERATE-STRONG | D10: TPM-backed attestation where even a fabric administrator cannot inspect a shielded VM's disk or state. Microsoft publishes a Guarded Fabric Planning Guide aimed specifically at HOSTING PROVIDERS. VMware has vTPM for encryption at rest but no equivalent attestation service preventing a rogue fabric admin from reaching tenant VM state. | E10: Strong for a multi-tenant hosting trust story specifically. Much weaker for a single-tenant enterprise, where nobody is worried about their own admins.
A11: Security | B11: ESXi has a documented history as a named ransomware target. | C11: MODERATE | D11: ESXiArgs (Feb 2023) mass-exploited an ESXi OpenSLP flaw — CISA alert AA23-039A. CVE-2024-37085: ESXi auto-grants full admin to any AD group literally named 'ESX Admins' without validating it exists; actively exploited by Storm-0506, Storm-1175, Octo Tempest and Manatee Tempest to deploy Akira and Black Basta. | E11: The CVE and the CISA alert are independently verifiable — lead with those. Microsoft's claim that ESXi-targeting IR engagements 'more than doubled in three years' is Microsoft's own IR data about a competitor; use it as colour, not as the load-bearing claim.
A12: Scale | B12: Hyper-V wins the per-VM spec sheet by a wide margin. | C12: STRONG (for rebuttal only) | D12: WS2025: 2,048 vCPUs/VM and 240 TB RAM/VM, vs vSphere 8's 768 vCPUs and 24 TB. Host: 2,048 logical processors vs 896. Both figures from each vendor's own published maximums. | E12: Use ONLY to rebut 'Hyper-V doesn't scale'. Almost nothing needs a 768-vCPU VM, let alone 2,048. Do not lead with '4 petabytes of host RAM' — it reads as marketing even though it is Microsoft's published number. And know that vSphere wins cluster node count, 96 vs 64.
A13: DR | B13: Hyper-V Replica is free and built in. SRM is a separately licensed product. | C13: MODERATE | D13: Hyper-V Replica ships with the Hyper-V role at no extra cost. On the VMware side, DR orchestration is now VCF Protection & Recovery (SRM absorbed), with local protection, remote replication, site recovery, multitenancy and cyber recovery carrying DIFFERENT commercial prerequisites. | E13: Real cost advantage. But Hyper-V Replica is VM-level async replication, NOT SRM-grade orchestrated failover with runbooks. Do not claim parity — claim 'free DR-lite included' and price orchestration separately if the customer needs it.
A14: Ecosystem | B14: Backup vendor support is at parity, not second-class. | C14: STRONG | D14: Veeam, Commvault, Rubrik and Cohesity all maintain first-class Hyper-V support in current products. Veeam maintains parallel Hyper-V and vSphere guides at the same doc version and has supported Hyper-V natively since the v6/v8 era. | E14: Directly kills a common objection that is roughly a decade out of date.
A15: Ecosystem | B15: Linux guest support is a solved problem. | C15: STRONG | D15: Linux Integration Services has been upstream in the mainline kernel since the 3.x series — it is not a bolt-on driver pack. Microsoft publishes current, maintained support matrices for RHEL, CentOS, Ubuntu, Debian, Oracle Linux, Rocky and SUSE. VMM 2025 added Ubuntu 24.04, RHEL 9, Debian 12/13, Oracle Linux 9, Rocky 8/9. | E15: The 'Linux runs badly on Hyper-V' objection was legitimate around 2012-2014. It is not current. Enlightened I/O gives near-native disk and network performance.
... A19: Hybrid | B19: Azure Hybrid Benefit has no vSphere equivalent. | C19: MODERATE | D19: SA-covered Windows Server cores run Azure VMs at the Linux base compute rate, waive the Azure Local host fee, and cover AKS on Windows Server / Azure Local at no extra licence cost. | E19: Only matters to customers with a real Azure trajectory. Strong when the pitch includes a hybrid story, irrelevant for pure on-prem.
A21: DO NOT CLAIM THESE — a VMware architect will correct you on the spot, and you will lose the technical win
A22: The tempting claim | B22: Why it is wrong
A23: ReFS + Veeam Fast Clone is a Hyper-V advantage | B23: FALSE. Fast Clone is a backup REPOSITORY filesystem feature. Veeam documents it for ReFS repositories backing up vSphere too. It works identically regardless of hypervisor.
A24: Live migration without shared storage is unique to Hyper-V | B24: FALSE. vMotion has supported migration without shared storage since vSphere 5.1. This is parity.
A25: Hyper-V's soft/hard cluster affinity is better than DRS rules | B25: FALSE. DRS has had 'must run on/with' (hard) and 'should run on/with' (soft) rules for years. Parity.
A26: Production Checkpoints beat VMware snapshots | B26: OVERSTATED. VMware snapshots are VSS-quiesced via VMware Tools on Windows guests. Functionally close to a wash.
A27: Nested virtualization is a Hyper-V differentiator | B27: FALSE. Nested ESXi is widely supported and heavily used for labs and CI. Parity.
A28: vSAN costs extra, S2D is free | B28: HALF TRUE AND NOW MISLEADING. vSAN is bundled into the VCF 9 subscription. The honest version is 'S2D is included in a licence you already need', not 'vSAN is an expensive add-on'.
A29: Hyper-V is X% faster than ESXi (or vice versa) | B29: NO CREDIBLE SOURCE EXISTS. There is no independent, methodologically sound, current benchmark comparing WS2025 Hyper-V to vSphere 8/VCF 9. Refuse the number in BOTH directions — and say so if a competitor cites one.
A30: Lots of major hosters run Hyper-V | B30: UNSUPPORTABLE. No credible public case studies at vSphere-comparable hosting scale were found. Use the SPLA-vs-VCSP program argument instead — that one is documented.
A31: Free Hyper-V Server is still available | B31: FALSE. Hyper-V Server 2019 was the last standalone free edition. The Hyper-V ROLE is free to enable, but a Windows Server licence is required. Moot for HAAS since you buy Datacenter anyway — but do not pretend otherwise.
A34: THE HONEST LOSSES — brief every SE on these so they are never ambushed
A35: Fault Tolerance (lockstep) | B35: No Hyper-V equivalent exists. Clustering plus Replica gives fast failover with a brief interruption; FT gives lockstep dual execution with zero interruption. Structural — do not spin it.
A36: DRS maturity | B36: SCVMM Dynamic Optimization is scheduled and threshold-based. DRS is a continuous predictive placement engine refined over two decades. The gap has narrowed (DRS is now in the base VCF subscription, and vSphere Standard never had it) but it is real.
A37: Cluster node ceiling | B37: vSphere allows 96 nodes per cluster; Windows Failover Clustering allows 64. A genuine vSphere edge at extreme scale.
A38: Third-party ecosystem breadth | B38: vSphere has two more decades of storage, networking and monitoring partner integrations. Real and structural — do not contest it.
A39: Independent performance validation | B39: Neither side has a credible current public benchmark. This cuts both ways — refuse the number in both directions.
A40: Automation rework | B40: PowerCLI and the Hyper-V PowerShell modules are different APIs. Terraform and Ansible support for Hyper-V is community-maintained, not first-party. Broadcom ships its own terraform-provider-vcf. Quantify the rework honestly in the TCO.

Sheet Objection Handling
A1: Objection Handling — VMware-Native Customers
A2: The verdict column matters as much as the answer. Conceding a true objection early buys credibility for the ones you can actually win.
A4: The objection | B4: Verdict | C4: The factual answer | D4: What to concede — say it before they do
A5: "Hyper-V doesn't scale." | B5: FALSE AS STATED | C5: WS2025 Hyper-V: 2,048 vCPUs/VM, 240 TB RAM/VM, 2,048 logical processors/host — against vSphere 8's 768 vCPUs and 24 TB RAM. Both from each vendor's own published maximums. | D5: Concede the one they may know: vSphere allows 96 nodes per cluster, Hyper-V 64. Say it before they do.
A6: "There's no DRS." | B6: PARTIALLY TRUE — ANSWER HONESTLY | C6: Native Failover Clustering has Node Fairness: basic, free, threshold-based. A true DRS equivalent (Dynamic Optimization) requires System Center VMM and runs on a schedule (default every 10 min, 10-1440 configurable) with a 1-5 aggressiveness scale. | D6: Do NOT claim parity. DRS is a continuous, predictive placement engine refined over two decades. Note in passing that vSphere Standard never included DRS either — it needed Enterprise Plus, and now the VCF bundle.
A7: "The management tools are bad." | B7: OUTDATED, WITH A KERNEL OF TRUTH | C7: Legacy Hyper-V Manager and the VMM console are genuinely dated. WAC 2606 is a modern web GUI, and WAC Virtualization Mode (vMode) is a purpose-built fleet manager targeting 1,000 hosts / 25,000 VMs. | D7: Be straight that vMode is still Public Preview. Overselling a preview product to an architect is how you lose the technical win.
A8: "Microsoft is killing System Center." | B8: FALSE | C8: System Center 2025 GA'd November 2024 with an active Update Rollup cadence. Mainstream support runs to 9 Jan 2030, extended support to 10 Jan 2035. | D8: Concede the real trend: Microsoft IS narrowing System Center's Azure-facing surface. SPF is discontinued and native Azure VM management was removed in 2025, redirected to Arc. The product is supported; its cloud ambitions moved to Arc.
A9: "Linux doesn't run well on Hyper-V." | B9: OUTDATED — CIRCA 2012 OBJECTION | C9: Linux Integration Services is upstream in the mainline kernel, not a bolt-on. Microsoft maintains current support matrices for RHEL, CentOS, Ubuntu, Debian, Oracle Linux, Rocky and SUSE. Enlightened I/O gives near-native disk and network performance. | D9: Offer to run their actual distro in the HAAS lab. This objection dies fastest with a demo.
A10: "Nobody uses Hyper-V for hosting." | B10: DO NOT FIGHT THIS ONE DIRECTLY | C10: No credible public case studies at vSphere-comparable hosting scale were found. Do not manufacture a customer list. | D10: REDIRECT to the program argument, which is documented: SPLA is open and stable; Broadcom terminated VCSP White Label resale and closed VCSP Advantage to invite-only with reportedly ~19 US providers left. Ask them who their provider will be in 2028.
A11: "Migration is too risky." | B11: ADDRESS WITH TOOLING, NOT RISK DENIAL | C11: SCVMM V2V is ~4x faster in the 2025 release. Azure Migrate, the WAC VM Conversion extension (preview), and third parties (Veeam, Zerto, Carbonite, NAKIVO) all have paths. Shared-nothing live migration removes the identical-shared-storage blocker during transition. | D11: Frame as 'de-risked by phased coexistence', never 'risk-free'. Note the Classic plane has NO native V2V — the migration tool is a separate decision from the management plane.
A12: "The free hypervisor was discontinued." | B12: TRUE — CONFIRM IT, DON'T DEFLECT | C12: Hyper-V Server 2019 was the last standalone free edition. The Hyper-V role is free to enable but requires a Windows Server licence underneath. | D12: Moot for HAAS: you are buying Windows Server Datacenter regardless, for the unlimited-guest-OSE benefit. Say that plainly.
A13: "S2D isn't as good as vSAN." | B13: DON'T FIGHT ON TECHNICAL MERITS | C13: No credible independent benchmark supports or refutes this cleanly in either direction. | D13: Redirect to licensing: S2D is included in a Datacenter licence you already need. But be careful — vSAN is now BUNDLED into VCF 9's subscription, so the old 'vSAN is an expensive add-on' line is stale. And offer SAN: HAAS runs Pure today, and the sizing tool supports SAN, S2D or hybrid.
A14: "We'll lose our automation investment." | B14: PARTIALLY TRUE — QUANTIFY IT | C14: PowerCLI and the Hyper-V PowerShell modules are different APIs. There is real rework. Terraform and Ansible have Hyper-V providers but they are COMMUNITY-maintained, not first-party — unlike Broadcom's own terraform-provider-vcf. | D14: This is a genuine migration cost. Put a number on it in the TCO rather than waving it away. Note that Windows-heavy shops usually already have PowerShell skills in house.
A15: "We'll have weaker DR." | B15: PARTIALLY TRUE — SCOPE IT | C15: Hyper-V Replica is free and built in, but it is VM-level async replication, not runbook orchestration. VMware's answer is now VCF Protection & Recovery, with SRM absorbed into it. | D15: Do not oversell Replica as a 1:1 SRM replacement. If they need orchestrated failover with runbooks, price a third-party DR tool into the deal.
A16: "Broadcom's partner changes don't affect us — we're the customer." | B16: FOR HAAS IT IS THE WHOLE POINT | C16: HAAS IS the service provider. The White Label / rental resale model ended 31 Oct 2025; the VCSP Advantage program closed to invite-only 26 Jan 2026; new or renewed VCSP contracts must be coterminous with an existing commitment. | D16: Reframe from price to access. The question is not 'what will VMware cost in 2028' but 'will we be permitted to sell it in 2028'.

Sheet Platform Limits
A1: Platform Limits & Capabilities
A2: Fact-checked Windows Server 2025 Hyper-V, clustering, storage, and management-plane limits. Maximums are not design targets.
A4: Category | B4: Scope | C4: Capability / limit | D4: Published value | E4: Applies to | F4: Basis | G4: Verified | H4: Source | I4: Qualification / design note
A5: Virtual machine | B5: Generation 2 VM | C5: Virtual processors | D5: 2,048 | E5: Windows Server 2025 Hyper-V host | F5: MS | G5: 2026-08-20 | H5: https://learn.microsoft.com/windows-server/virtualization/hyper-v/maximum-scale-limits | I5: Generation 1 is limited to 64 virtual processors.
A6: Virtual machine | B6: Generation 2 VM | C6: Memory | D6: 240 TB | E6: Windows Server 2025 Hyper-V host | F6: MS | G6: 2026-08-20 | H6: https://learn.microsoft.com/windows-server/virtualization/hyper-v/maximum-scale-limits | I6: The guest operating system can impose a lower limit.
A7: Virtual machine | B7: Virtual disk | C7: VHDX capacity | D7: 64 TB | E7: Windows Server 2025 Hyper-V host | F7: MS | G7: 2026-08-20 | H7: https://learn.microsoft.com/windows-server/virtualization/hyper-v/maximum-scale-limits | I7: Legacy VHD is limited to 2,040 GB.
A8: Virtual machine | B8: Generation 2 VM | C8: Virtual SCSI devices | D8: 256 | E8: Windows Server 2025 Hyper-V host | F8: MS | G8: 2026-08-20 | H8: https://learn.microsoft.com/windows-server/virtualization/hyper-v/maximum-scale-limits | I8: Four SCSI controllers with up to 64 devices each.
A9: Virtual machine | B9: Generation 2 VM | C9: Virtual network adapters | D9: 64 standard | E9: Windows Server 2025 Hyper-V host | F9: MS | G9: 2026-08-20 | H9: https://learn.microsoft.com/windows-server/virtualization/hyper-v/maximum-scale-limits
A10: Virtual machine | B10: VM | C10: Checkpoints | D10: 50 | E10: Windows Server 2025 Hyper-V host | F10: MS | G10: 2026-08-20 | H10: https://learn.microsoft.com/windows-server/virtualization/hyper-v/maximum-scale-limits | I10: Practical use also depends on available storage.
A11: Hyper-V host | B11: Physical host | C11: Running virtual machines | D11: 1,024 | E11: Windows Server 2025 | F11: MS | G11: 2026-08-20 | H11: https://learn.microsoft.com/windows-server/virtualization/hyper-v/maximum-scale-limits | I11: A supported maximum, not a recommended consolidation target.
A12: Hyper-V host | B12: Physical host | C12: Logical processors | D12: 2,048 | E12: Windows Server 2025 | F12: MS | G12: 2026-08-20 | H12: https://learn.microsoft.com/windows-server/virtualization/hyper-v/maximum-scale-limits
A13: Hyper-V host | B13: Physical host | C13: Virtual processors in use | D13: 2,048 | E13: Windows Server 2025 | F13: MS | G13: 2026-08-20 | H13: https://learn.microsoft.com/windows-server/virtualization/hyper-v/maximum-scale-limits | I13: Hyper-V imposes no fixed virtual-processor-to-logical-processor ratio.
A14: Hyper-V host | B14: Physical host | C14: Memory | D14: 4 PB with 5-level paging; 256 TB with 4-level paging | E14: Windows Server 2025 | F14: MS | G14: 2026-08-20 | H14: https://learn.microsoft.com/windows-server/virtualization/hyper-v/maximum-scale-limits | I14: Platform firmware and hardware can impose lower limits.
A15: Failover cluster | B15: Hyper-V cluster | C15: Nodes per cluster | D15: 64 | E15: Supported Windows Server versions | F15: MS | G15: 2026-08-20 | H15: https://learn.microsoft.com/windows-server/virtualization/hyper-v/maximum-scale-limits
A16: Failover cluster | B16: Hyper-V cluster | C16: Running virtual machines | D16: 8,000 | E16: Supported Windows Server versions | F16: MS | G16: 2026-08-20 | H16: https://learn.microsoft.com/windows-server/virtualization/hyper-v/maximum-scale-limits | I16: Capacity planning and failure-domain headroom still apply.
